Workbook

Sheet KOLOM ISIAN
A1: KEMENTERIAN KETENAGAKERJAAN REPUBLIK INDONESIA
A2: DIREKTORAT JENDERAL PEMBINAAN PELATIHAN DAN PRODUKTIVITAS
A3: BALAI PELATIHAN VOKASI DAN PRODUKTIVITAS
A4: Jln. DI Panjaitan No 226 Tlp. 3190427 Kendari 93117
A6: HASIL ANALISIS EVALUASI
A7: PELATIHAN KOMPETENSI BERBASIS PARIWISATA DAN INDUSTRI KREATIF
A8: PROGRAM PELATIHAN DASAR ASISTEN PEMBUAT PAKAIAN PAKET 2
A9: TGL Senin 3 Agustus S.D Jumat 28 Agustus 2026
A11: No | B11: Materi Penilaian | C11: Peserta (Responden Kusioner) | AC11: Ket.
C13: 1 | D13: 2 | E13: 3 | F13: 4 | G13: 5 | H13: 6 | I13: 7 | J13: 8 | K13: 9 | L13: 10 | M13: 11 | N13: 12 | O13: 13 | P13: 14 | Q13: 15 | R13: 16 | S13: JUMLAH | T13: 22 | U13: 23 | V13: 24 | W13: 25 | X13: 26 | Y13: 27 | Z13: 28 | AA13: 29 | AB13: Jumlah
A14: I | B14: MATERI PELATIHAN
A15: 1 | B15: Apakah informasi pelatihan mudah untuk didapatkan | C15: 5 | D15: 5 | E15: 5 | F15: 5 | G15: 4 | H15: 4 | I15: 4 | J15: 4 | K15: 5 | L15: 5 | M15: 3 | N15: 4 | S15: =SUM(C15:R15)/12 -> 4.4166667 | AB15: =SUM(M15:AA15) -> 11.416667 | AC15: =IF(S15>=5,"SANGAT BAIK",IF(S15>=4,"BAIK",IF(S15>=3,"CUKUP",IF(S15>=2,"KURANG",IF(S15>=0,"TIDAK BAIK"))))) -> BAIK
A16: 2 | B16: Apakah pendaftaran dan tahapannya mudah untuk dilakukan | C16: 3 | D16: 5 | E16: 5 | F16: 5 | G16: 4 | H16: 5 | I16: 4 | J16: 4 | K16: 2 | L16: 5 | M16: 4 | N16: 4 | S16: =SUM(C16:R16)/12 -> 4.1666667 | AB16: =SUM(M16:AA16) -> 12.166667 | AC16: =IF(S16>=5,"SANGAT BAIK",IF(S16>=4,"BAIK",IF(S16>=3,"CUKUP",IF(S16>=2,"KURANG",IF(S16>=0,"TIDAK BAIK"))))) -> BAIK
A17: 3 | B17: Apakah petunjuk tata cara pendaftaran jelas dan mudah dipahami | C17: 3 | D17: 5 | E17: 5 | F17: 5 | G17: 5 | H17: 4 | I17: 4 | J17: 4 | K17: 4 | L17: 5 | M17: 5 | N17: 4 | S17: =SUM(C17:R17)/12 -> 4.4166667 | AB17: =SUM(M17:AA17) -> 13.416667 | AC17: =IF(S17>=5,"SANGAT BAIK",IF(S17>=4,"BAIK",IF(S17>=3,"CUKUP",IF(S17>=2,"KURANG",IF(S17>=0,"TIDAK BAIK"))))) -> BAIK
A18: 4 | B18: Apakah program pelatihan jelas dan mudah dipahami | C18: 5 | D18: 5 | E18: 3 | F18: 4 | G18: 5 | H18: 5 | I18: 5 | J18: 3 | K18: 5 | L18: 5 | M18: 5 | N18: 5 | S18: =SUM(C18:R18)/12 -> 4.5833333 | AC18: =IF(S18>=5,"SANGAT BAIK",IF(S18>=4,"BAIK",IF(S18>=3,"CUKUP",IF(S18>=2,"KURANG",IF(S18>=0,"TIDAK BAIK"))))) -> BAIK
S19: =AVERAGE(S15:S18) -> 4.3958333 | AC19: =IF(S19>=5,"SANGAT BAIK",IF(S19>=4,"BAIK",IF(S19>=3,"CUKUP",IF(S19>=2,"KURANG",IF(S19>=0,"TIDAK BAIK"))))) -> BAIK
A20: No | B20: Materi Penilaian | C20: Peserta (Responden Kusioner) | AC20: Keterangan
C22: 1 | D22: 2 | E22: 3 | F22: 4 | G22: 5 | H22: 6 | I22: 7 | J22: 8 | K22: 9 | L22: 10 | M22: 11 | N22: 12 | O22: 13 | P22: 14 | Q22: 15 | R22: 16 | S22: JUMLAH | T22: 22 | U22: 23 | V22: 24 | W22: 25 | X22: 26 | Y22: 27 | Z22: 28 | AA22: 29 | AB22: Jumlah
A23: II | B23: PROGRAM PELATIHAN
A24: 1 | B24: Apakah program pelatihan menarik | C24: 5 | D24: 5 | E24: 5 | F24: 5 | G24: 5 | H24: 5 | I24: 4 | J24: 4 | K24: 4 | L24: 5 | M24: 4 | N24: 5 | S24: =SUM(C24:R24)/12 -> 4.6666667 | AB24: =SUM(M24:AA24) -> 13.666667 | AC24: =IF(S24>=5,"SANGAT BAIK",IF(S24>=4,"BAIK",IF(S24>=3,"CUKUP",IF(S24>=2,"KURANG",IF(S24>=0,"TIDAK BAIK"))))) -> BAIK
A25: 2 | B25: Apakah program pelatihan bermanfaat | C25: 5 | D25: 5 | E25: 5 | F25: 5 | G25: 5 | H25: 5 | I25: 5 | J25: 5 | K25: 5 | L25: 5 | M25: 5 | N25: 5 | S25: =SUM(C25:R25)/12 -> 5 | AC25: =IF(S25>=5,"SANGAT BAIK",IF(S25>=4,"BAIK",IF(S25>=3,"CUKUP",IF(S25>=2,"KURANG",IF(S25>=0,"TIDAK BAIK"))))) -> SANGAT BAIK
A26: 3 | B26: Apakah program pelatihan berhasil meningkatkan kompetensi Anda | C26: 5 | D26: 5 | E26: 5 | F26: 5 | G26: 5 | H26: 5 | I26: 3 | J26: 4 | K26: 5 | L26: 5 | M26: 4 | N26: 5 | S26: =SUM(C26:R26)/12 -> 4.6666667 | AC26: =IF(S26>=5,"SANGAT BAIK",IF(S26>=4,"BAIK",IF(S26>=3,"CUKUP",IF(S26>=2,"KURANG",IF(S26>=0,"TIDAK BAIK"))))) -> BAIK
A27: 4 | B27: Apakah durasi untuk menyelesaikan pelatihan sudah sesuai? | C27: 3 | D27: 5 | E27: 5 | F27: 5 | G27: 3 | H27: 4 | I27: 4 | J27: 4 | K27: 4 | L27: 4 | M27: 4 | N27: 3 | S27: =SUM(C27:R27)/12 -> 4 | AC27: =IF(S27>=5,"SANGAT BAIK",IF(S27>=4,"BAIK",IF(S27>=3,"CUKUP",IF(S27>=2,"KURANG",IF(S27>=0,"TIDAK BAIK"))))) -> BAIK
S28: =AVERAGE(S24:S27) -> 4.5833333 | AC28: =IF(S28>=5,"SANGAT BAIK",IF(S28>=4,"BAIK",IF(S28>=3,"CUKUP",IF(S28>=2,"KURANG",IF(S28>=0,"TIDAK BAIK"))))) -> BAIK
A29: No | B29: Materi Penilaian | C29: Peserta (Responden Kusioner) | AC29: Ket.
C30: 1 | D30: 2 | E30: 3 | F30: 4 | G30: 5 | H30: 6 | I30: 7 | J30: 8 | K30: 9 | L30: 10 | M30: 11 | N30: 12 | O30: 13 | P30: 14 | Q30: 15 | R30: 16 | S30: JUMLAH
A31: III | B31: INSTRUKTUR | C31: Nama Instruktur : Kristina, Nathalia
A32: 1 | B32: Apakah Instrukur menguasai program pelatihan yang disampaikan | C32: 5 | D32: 5 | E32: 5 | F32: 5 | G32: 5 | H32: 5 | I32: 5 | J32: 5 | K32: 5 | L32: 5 | M32: 5 | N32: 5 | S32: =SUM(C32:R32)/12 -> 5 | AC32: =IF(S32>=5,"SANGAT BAIK",IF(S32>=4,"BAIK",IF(S32>=3,"CUKUP",IF(S32>=2,"KURANG",IF(S32>=0,"TIDAK BAIK"))))) -> SANGAT BAIK
A33: 2 | B33: Bagaimana kemampuan Instruktur dalam menyampaikan program pelatihan | C33: 5 | D33: 5 | E33: 4 | F33: 5 | G33: 5 | H33: 5 | I33: 4 | J33: 5 | K33: 5 | L33: 5 | M33: 5 | N33: 5 | S33: =SUM(C33:R33)/12 -> 4.8333333 | AC33: =IF(S33>=5,"SANGAT BAIK",IF(S33>=4,"BAIK",IF(S33>=3,"CUKUP",IF(S33>=2,"KURANG",IF(S33>=0,"TIDAK BAIK"))))) -> BAIK
A34: 3 | B34: Bagaimana kemampuan Instruktur dalam mengelola Peserta Pelatihan | C34: 5 | D34: 5 | E34: 5 | F34: 5 | G34: 5 | H34: 5 | I34: 5 | J34: 5 | K34: 5 | L34: 5 | M34: 5 | N34: 4 | S34: =SUM(C34:R34)/12 -> 4.9166667 | AC34: =IF(S34>=5,"SANGAT BAIK",IF(S34>=4,"BAIK",IF(S34>=3,"CUKUP",IF(S34>=2,"KURANG",IF(S34>=0,"TIDAK BAIK"))))) -> BAIK
A35: 4 | B35: Bagaimana sikap, disiplin, penampilan, dan teladan Instruktur selama pelatihan | C35: 5 | D35: 5 | E35: 5 | F35: 5 | G35: 5 | H35: 5 | I35: 5 | J35: 5 | K35: 5 | L35: 5 | M35: 5 | N35: 4 | S35: =SUM(C35:R35)/12 -> 4.9166667 | AC35: =IF(S35>=5,"SANGAT BAIK",IF(S35>=4,"BAIK",IF(S35>=3,"CUKUP",IF(S35>=2,"KURANG",IF(S35>=0,"TIDAK BAIK"))))) -> BAIK
S36: =AVERAGE(S32:S35) -> 4.9166667 | AC36: =IF(S36>=5,"SANGAT BAIK",IF(S36>=4,"BAIK",IF(S36>=3,"CUKUP",IF(S36>=2,"KURANG",IF(S36>=0,"TIDAK BAIK"))))) -> BAIK
A37: NO. | B37: Materi Penilaian | C37: Peserta (Responden Kusioner) | AC37: Ket.
C38: 1 | D38: 2 | E38: 3 | F38: 4 | G38: 5 | H38: 6 | I38: 7 | J38: 8 | K38: 9 | L38: 10 | M38: 11 | N38: 12 | O38: 13 | P38: 14 | Q38: 15 | R38: 16 | S38: JUMLAH
A39: IV | B39: PENYELENGGARAAN PELATIHAN
A40: 1 | B40: Bagaimana pelayanan petugas terhadap Peserta Pelatihan | C40: 3 | D40: 5 | E40: 4 | F40: 5 | G40: 5 | H40: 5 | I40: 4 | J40: 4 | K40: 4 | L40: 5 | M40: 4 | N40: 5 | S40: =SUM(C40:R40)/12 -> 4.4166667 | AC40: =IF(S40>=5,"SANGAT BAIK",IF(S40>=4,"BAIK",IF(S40>=3,"CUKUP",IF(S40>=2,"KURANG",IF(S40>=0,"TIDAK BAIK"))))) -> BAIK
A41: 2 | B41: Apakah pelaksanaan jadwal pelatihan sudah sesuai dengan rencana | C41: 5 | D41: 5 | E41: 5 | F41: 5 | G41: 4 | H41: 5 | I41: 4 | J41: 4 | K41: 5 | L41: 5 | M41: 4 | N41: 4 | S41: =SUM(C41:R41)/12 -> 4.5833333 | AC41: =IF(S41>=5,"SANGAT BAIK",IF(S41>=4,"BAIK",IF(S41>=3,"CUKUP",IF(S41>=2,"KURANG",IF(S41>=0,"TIDAK BAIK"))))) -> BAIK
A42: 3 | B42: Apakah perlengkapan Peserta Pelatihan (training material) diberikan tepat waktu? (contoh: atribut pelatihan/seragam/Alat Pelindung Diri/modul/materi/ATK/bahan/ konten/dll) | C42: 3 | D42: 5 | E42: 4 | F42: 5 | G42: 5 | H42: 3 | I42: 5 | J42: 4 | K42: 5 | L42: 5 | M42: 2 | N42: 3 | S42: =SUM(C42:R42)/12 -> 4.0833333 | AC42: =IF(S42>=5,"SANGAT BAIK",IF(S42>=4,"BAIK",IF(S42>=3,"CUKUP",IF(S42>=2,"KURANG",IF(S42>=0,"TIDAK BAIK"))))) -> BAIK
A43: 4 | B43: Apakah sarana/prasarana/fasilitas pelatihan sudah memadai?(contoh: kelas/workshop/mesin/alat/website sistem manajemen pembelajaran/dll) | C43: 5 | D43: 5 | E43: 5 | F43: 5 | G43: 5 | H43: 4 | I43: 5 | J43: 5 | K43: 5 | L43: 5 | M43: 4 | N43: 4 | S43: =SUM(C43:R43)/12 -> 4.75 | AC43: =IF(S43>=5,"SANGAT BAIK",IF(S43>=4,"BAIK",IF(S43>=3,"CUKUP",IF(S43>=2,"KURANG",IF(S43>=0,"TIDAK BAIK"))))) -> BAIK
A44: 5 | B44: Apakah sarana/prasarana/fasilitas penunjang pelatihan sudah memadai (contoh: asrama/tempat ibadah/kantin/toilet/perpustakaan/website lembaga pelatihan/dll) | C44: 5 | D44: 5 | E44: 5 | F44: 5 | G44: 5 | H44: 5 | I44: 4 | J44: 4 | K44: 5 | L44: 5 | M44: 3 | N44: 4 | S44: =SUM(C44:R44)/12 -> 4.5833333 | AC44: =IF(S44>=5,"SANGAT BAIK",IF(S44>=4,"BAIK",IF(S44>=3,"CUKUP",IF(S44>=2,"KURANG",IF(S44>=0,"TIDAK BAIK"))))) -> BAIK
...

Sheet Histogram
A1: KEMENTERIAN KETENAGAKERJAAN RI
A2: DIREKTORAT JENDERAL PEMBINAAN PELATIHAN DAN PRODUKTIVITAS
A3: =Penyelenggaraan!A3 -> BALAI PELATIHAN VOKASI DAN PRODUKTIVITAS
A4: Jln. DI Panjaitan No 226 Tlp. 3190427 Kendari 93117
A6: ='Materi Pelatihan'!$A$6:$AC$6 -> HASIL EVALUASI
A7: ='Materi Pelatihan'!A7:AC7 -> PELATIHAN KOMPETENSI BERBASIS PARIWISATA DAN INDUSTRI KREATIF
A8: ='Materi Pelatihan'!A8:AC8 -> PROGRAM PELATIHAN DASAR ASISTEN PEMBUAT PAKAIAN PAKET 2
A9: ='Materi Pelatihan'!A9:AC9 -> TGL Senin 3 Agustus S.D Jumat 28 Agustus 2026
A11: NO | B11: ASPEK PENILAIAN | C11: NILAI AKHIR | D11: KETERANGAN
A12: 1 | B12: MATERI PELATIHAN | C12: ='KOLOM ISIAN'!S19 -> 4.3958333 | D12: =IF(C12>=5,"SANGAT BAIK",IF(C12>=4,"BAIK",IF(C12>=3,"CUKUP",IF(C12>=2,"KURANG",IF(C12>=0,"TIDAK BAIK"))))) -> BAIK
A13: 2 | B13: PROGRAM PELATIHAN | C13: ='KOLOM ISIAN'!S28 -> 4.5833333 | D13: =IF(C13>=5,"SANGAT BAIK",IF(C13>=4,"BAIK",IF(C13>=3,"CUKUP",IF(C13>=2,"KURANG",IF(C13>=0,"TIDAK BAIK"))))) -> BAIK | F13: Instruktur
A14: 3 | B14: INSTRUKTUR | C14: ='KOLOM ISIAN'!S36 -> 4.9166667 | D14: =IF(C14>=5,"SANGAT BAIK",IF(C14>=4,"BAIK",IF(C14>=3,"CUKUP",IF(C14>=2,"KURANG",IF(C14>=0,"TIDAK BAIK"))))) -> BAIK
A15: 4 | B15: PENYELENGGARAAN PELATIHAN | C15: ='KOLOM ISIAN'!S45 -> 4.4833333 | D15: =IF(C15>=5,"SANGAT BAIK",IF(C15>=4,"BAIK",IF(C15>=3,"CUKUP",IF(C15>=2,"KURANG",IF(C15>=0,"TIDAK BAIK"))))) -> BAIK
A16: GRAND TOTAL | C16: =AVERAGE(C12:C15) -> 4.5947917 | D16: =IF(C16>=5,"SANGAT BAIK",IF(C16>=4,"BAIK",IF(C16>=3,"CUKUP",IF(C16>=2,"KURANG",IF(C16>=0,"TIDAK BAIK"))))) -> BAIK

Sheet Materi Pelatihan
A1: KEMENTERIAN KETENAGAKERJAAN REPUBLIK INDONESIA
A2: DIREKTORAT JENDERAL PEMBINAAN PELATIHAN DAN PRODUKTIVITAS
A3: ='KOLOM ISIAN'!A3:AC3 -> BALAI PELATIHAN VOKASI DAN PRODUKTIVITAS
A4: Jln. DI Panjaitan No 226 Tlp. 3190427 Kendari 93117
A6: HASIL EVALUASI
A7: ='KOLOM ISIAN'!A7:AC7 -> PELATIHAN KOMPETENSI BERBASIS PARIWISATA DAN INDUSTRI KREATIF
A8: ='KOLOM ISIAN'!A8:AC8 -> PROGRAM PELATIHAN DASAR ASISTEN PEMBUAT PAKAIAN PAKET 2
A9: ='KOLOM ISIAN'!A9:AC9 -> TGL Senin 3 Agustus S.D Jumat 28 Agustus 2026
A11: No | B11: Materi Penilaian | C11: Peserta (Responden Kusioner) | AC11: Ket.
C13: 1 | D13: 2 | E13: 3 | F13: 4 | G13: 5 | H13: 6 | I13: 7 | J13: 8 | K13: 9 | L13: 10 | M13: 11 | N13: 12 | O13: 13 | P13: 14 | Q13: 15 | R13: 16 | S13: JUMLAH | T13: 22 | U13: 23 | V13: 24 | W13: 25 | X13: 26 | Y13: 27 | Z13: 28 | AA13: 29 | AB13: Jumlah
A14: A | B14: MATERI PELATIHAN
A15: 1 | B15: Apakah informasi pelatihan mudah untuk didapatkan | C15: ='KOLOM ISIAN'!C15 -> 5 | D15: ='KOLOM ISIAN'!D15 -> 5 | E15: ='KOLOM ISIAN'!E15 -> 5 | F15: ='KOLOM ISIAN'!F15 -> 5 | G15: ='KOLOM ISIAN'!G15 -> 4 | H15: ='KOLOM ISIAN'!H15 -> 4 | I15: ='KOLOM ISIAN'!I15 -> 4 | J15: ='KOLOM ISIAN'!J15 -> 4 | ... R15: ='KOLOM ISIAN'!R15 -> 0 | S15: =SUM(C15:R15)/12 -> 4.4166667 | AB15: =SUM(M15:AA15) -> 11.416667 | AC15: =IF(S15>=5,"SANGAT BAIK",IF(S15>=4,"BAIK",IF(S15>=3,"CUKUP",IF(S15>=2,"KURANG",IF(S15>=0,"TIDAK BAIK"))))) -> BAIK
A16: 2 | B16: Apakah pendaftaran dan tahapannya mudah untuk dilakukan | C16: ='KOLOM ISIAN'!C16:R16 -> 3 | D16: ='KOLOM ISIAN'!D16:S16 -> 5 | E16: ='KOLOM ISIAN'!E16:T16 -> 5 | F16: ='KOLOM ISIAN'!F16:U16 -> 5 | G16: ='KOLOM ISIAN'!G16:V16 -> 4 | H16: ='KOLOM ISIAN'!H16:W16 -> 5 | I16: ='KOLOM ISIAN'!I16:X16 -> 4 | J16: ='KOLOM ISIAN'!J16:Y16 -> 4 | ... R16: ='KOLOM ISIAN'!R16:AG16 -> 0 | S16: =SUM(C16:R16)/12 -> 4.1666667 | AB16: =SUM(M16:AA16) -> 12.166667 | AC16: =IF(S16>=5,"SANGAT BAIK",IF(S16>=4,"BAIK",IF(S16>=3,"CUKUP",IF(S16>=2,"KURANG",IF(S16>=0,"TIDAK BAIK"))))) -> BAIK
A17: 3 | B17: Apakah petunjuk tata cara pendaftaran jelas dan mudah dipaham | C17: ='KOLOM ISIAN'!C17 -> 3 | D17: ='KOLOM ISIAN'!D17 -> 5 | E17: ='KOLOM ISIAN'!E17 -> 5 | F17: ='KOLOM ISIAN'!F17 -> 5 | G17: ='KOLOM ISIAN'!G17 -> 5 | H17: ='KOLOM ISIAN'!H17 -> 4 | I17: ='KOLOM ISIAN'!I17 -> 4 | J17: ='KOLOM ISIAN'!J17 -> 4 | ... O17: ='KOLOM ISIAN'!O17 -> 0 | P17: ='KOLOM ISIAN'!P17:AE17 -> 0 | Q17: ='KOLOM ISIAN'!Q17:AF17 -> 0 | R17: ='KOLOM ISIAN'!R17:AG17 -> 0 | S17: =SUM(C17:R17)/12 -> 4.4166667 | AB17: =SUM(M17:AA17) -> 13.416667 | AC17: =IF(S17>=5,"SANGAT BAIK",IF(S17>=4,"BAIK",IF(S17>=3,"CUKUP",IF(S17>=2,"KURANG",IF(S17>=0,"TIDAK BAIK"))))) -> BAIK
A18: 4 | B18: Apakah program pelatihan jelas dan mudah dipahami | C18: ='KOLOM ISIAN'!C18 -> 5 | D18: ='KOLOM ISIAN'!D18 -> 5 | E18: ='KOLOM ISIAN'!E18 -> 3 | F18: ='KOLOM ISIAN'!F18 -> 4 | G18: ='KOLOM ISIAN'!G18 -> 5 | H18: ='KOLOM ISIAN'!H18 -> 5 | I18: ='KOLOM ISIAN'!I18 -> 5 | J18: ='KOLOM ISIAN'!J18 -> 3 | ... O18: ='KOLOM ISIAN'!O18 -> 0 | P18: ='KOLOM ISIAN'!P18:AE18 -> 0 | Q18: ='KOLOM ISIAN'!Q18:AF18 -> 0 | R18: ='KOLOM ISIAN'!R18:AG18 -> 0 | S18: =SUM(C18:R18)/12 -> 4.5833333 | AB18: =SUM(M18:AA18) -> 14.583333 | AC18: =IF(S18>=5,"SANGAT BAIK",IF(S18>=4,"BAIK",IF(S18>=3,"CUKUP",IF(S18>=2,"KURANG",IF(S18>=0,"TIDAK BAIK"))))) -> BAIK
C19: JUMLAH | S19: =AVERAGE(S15:S18) -> 4.3958333 | AC19: =IF(S19>=5,"SANGAT BAIK",IF(S19>=4,"BAIK",IF(S19>=3,"CUKUP",IF(S19>=2,"KURANG",IF(S19>=0,"TIDAK BAIK"))))) -> BAIK
B27: Jumlah Peserta 16 orang
B28: ="responden evaluasi "& COUNTA('KOLOM ISIAN'!$C$15:$R$15)& " orang" -> responden evaluasi 12 orang

Sheet Program Pelatihan
A1: KEMENTERIAN KETENAGAKERJAAN RI
A2: DIREKTORAT JENDERAL PEMBINAAN PELATIHAN DAN PRODUKTIVITAS
A3: =INSTRUKTUR!A3 -> BALAI PELATIHAN VOKASI DAN PRODUKTIVITAS
A4: Jln. DI Panjaitan No 226 Tlp. 3190427 Kendari 93117
A6: HASIL EVALUASI
A7: ='Materi Pelatihan'!A7:AC7 -> PELATIHAN KOMPETENSI BERBASIS PARIWISATA DAN INDUSTRI KREATIF
A8: ='Materi Pelatihan'!A8:AC8 -> PROGRAM PELATIHAN DASAR ASISTEN PEMBUAT PAKAIAN PAKET 2
A9: ='Materi Pelatihan'!A9:AC9 -> TGL Senin 3 Agustus S.D Jumat 28 Agustus 2026
A11: No | B11: Program Penilaian | C11: Peserta (Responden Kusioner) | AC11: Keterangan
C13: 1 | D13: 2 | E13: 3 | F13: 4 | G13: 5 | H13: 6 | I13: 7 | J13: 8 | K13: 9 | L13: 10 | M13: 11 | N13: 12 | O13: 13 | P13: 14 | Q13: 15 | R13: 16 | S13: JUMLAH | T13: 22 | U13: 23 | V13: 24 | W13: 25 | X13: 26 | Y13: 27 | Z13: 28 | AA13: 29 | AB13: Jumlah
A14: II | B14: PROGRAM PELATIHAN
A15: 1 | B15: Apakah program pelatihan menarik | C15: ='KOLOM ISIAN'!C24 -> 5 | D15: ='KOLOM ISIAN'!D24 -> 5 | E15: ='KOLOM ISIAN'!E24 -> 5 | F15: ='KOLOM ISIAN'!F24 -> 5 | G15: ='KOLOM ISIAN'!G24 -> 5 | H15: ='KOLOM ISIAN'!H24 -> 5 | I15: ='KOLOM ISIAN'!I24 -> 4 | J15: ='KOLOM ISIAN'!J24 -> 4 | ... R15: ='KOLOM ISIAN'!R24 -> 0 | S15: =SUM(C15:R15)/12 -> 4.6666667 | AC15: =IF(S15>=2.95,"BAIK",IF(S15>=1.95,"CUKUP","KURANG")) -> BAIK
A16: 2 | B16: Apakah program pelatihan bermanfaat | C16: ='KOLOM ISIAN'!C25:R25 -> 5 | D16: ='KOLOM ISIAN'!D25:S25 -> 5 | E16: ='KOLOM ISIAN'!E25:T25 -> 5 | F16: ='KOLOM ISIAN'!F25:U25 -> 5 | G16: ='KOLOM ISIAN'!G25:V25 -> 5 | H16: ='KOLOM ISIAN'!H25:W25 -> 5 | I16: ='KOLOM ISIAN'!I25:X25 -> 5 | J16: ='KOLOM ISIAN'!J25:Y25 -> 5 | ... R16: ='KOLOM ISIAN'!R25:AG25 -> 0 | S16: =SUM(C16:R16)/12 -> 5 | AC16: =IF(S16>=2.95,"BAIK",IF(S16>=1.95,"CUKUP","KURANG")) -> BAIK
A17: 3 | B17: Apakah program pelatihan berhasil meningkatkan kompetensi Anda | C17: ='KOLOM ISIAN'!C26:R26 -> 5 | D17: ='KOLOM ISIAN'!D26:S26 -> 5 | E17: ='KOLOM ISIAN'!E26:T26 -> 5 | F17: ='KOLOM ISIAN'!F26:U26 -> 5 | G17: ='KOLOM ISIAN'!G26:V26 -> 5 | H17: ='KOLOM ISIAN'!H26:W26 -> 5 | I17: ='KOLOM ISIAN'!I26:X26 -> 3 | J17: ='KOLOM ISIAN'!J26:Y26 -> 4 | ... R17: ='KOLOM ISIAN'!R26:AG26 -> 0 | S17: =SUM(C17:R17)/12 -> 4.6666667 | AC17: =IF(S17>=2.95,"BAIK",IF(S17>=1.95,"CUKUP","KURANG")) -> BAIK
A18: 4 | B18: Apakah durasi untuk menyelesaikan pelatihan sudah sesuai? | C18: ='KOLOM ISIAN'!C27 -> 3 | D18: ='KOLOM ISIAN'!D27 -> 5 | E18: ='KOLOM ISIAN'!E27 -> 5 | F18: ='KOLOM ISIAN'!F27 -> 5 | G18: ='KOLOM ISIAN'!G27 -> 3 | H18: ='KOLOM ISIAN'!H27 -> 4 | I18: ='KOLOM ISIAN'!I27 -> 4 | J18: ='KOLOM ISIAN'!J27 -> 4 | ... R18: ='KOLOM ISIAN'!R27 -> 0 | S18: =SUM(C18:R18)/12 -> 4 | AC18: =IF(S18>=2.95,"BAIK",IF(S18>=1.95,"CUKUP","KURANG")) -> BAIK
C19: JUMLAH | S19: =AVERAGE(S15:S18) -> 4.5833333 | AC19: =IF(VALUE(S19)>=5,"SANGAT BAIK", IF(VALUE(S19)>=4,"BAIK", IF(VALUE(S19)>=3,"CUKUP", IF(VALUE(S19)>=2,"KURANG", IF(VALUE(S19)>=0,"TIDAK BAIK"))))) -> BAIK

Sheet INSTRUKTUR
A1: KEMENTERIAN KETENAGAKERJAAN RI
A2: DIREKTORAT JENDERAL PEMBINAAN PELATIHAN DAN PRODUKTIVITAS
A3: ='Materi Pelatihan'!A3:AC3 -> BALAI PELATIHAN VOKASI DAN PRODUKTIVITAS
A4: Jln. DI Panjaitan No 226 Tlp. 3190427 Kendari 93117
A7: HASIL EVALUASI
A8: ='Materi Pelatihan'!A7:AC7 -> PELATIHAN KOMPETENSI BERBASIS PARIWISATA DAN INDUSTRI KREATIF
A9: ='Materi Pelatihan'!A8:AC8 -> PROGRAM PELATIHAN DASAR ASISTEN PEMBUAT PAKAIAN PAKET 2
A10: ='Materi Pelatihan'!A9:AC9 -> TGL Senin 3 Agustus S.D Jumat 28 Agustus 2026
A12: No | B12: Materi Penilaian | C12: INSTRUKTUR : | N12: ='KOLOM ISIAN'!N20 -> 0 | AC12: Keterangan
C14: 1 | D14: 2 | E14: 3 | F14: 4 | G14: 5 | H14: 6 | I14: 7 | J14: 8 | K14: 9 | L14: 10 | M14: 11 | N14: 12 | O14: 13 | P14: 14 | Q14: 15 | R14: 16 | S14: JUMLAH | T14: 22 | U14: 23 | V14: 24 | W14: 25 | X14: 26 | Y14: 27 | Z14: 28 | AA14: 29 | AB14: Jumlah
A15: III | B15: INSTRUKTUR
A16: 1 | B16: Apakah Instrukur menguasai program pelatihan yang disampaikan | C16: ='KOLOM ISIAN'!C32 -> 5 | D16: ='KOLOM ISIAN'!D32 -> 5 | E16: ='KOLOM ISIAN'!E32 -> 5 | F16: ='KOLOM ISIAN'!F32 -> 5 | G16: ='KOLOM ISIAN'!G32 -> 5 | H16: ='KOLOM ISIAN'!H32 -> 5 | I16: ='KOLOM ISIAN'!I32 -> 5 | J16: ='KOLOM ISIAN'!J32 -> 5 | ... P16: ='KOLOM ISIAN'!P32 -> 0 | Q16: ='KOLOM ISIAN'!Q31:AF31 -> 0 | R16: ='KOLOM ISIAN'!R31:AG31 -> 0 | S16: =SUM(C16:R16)/12 -> 5 | AB16: =SUM(M16:AA16) -> 15 | AC16: =IF(S16>=2.95,"BAIK",IF(S16>=1.95,"CUKUP","KURANG")) -> BAIK
A17: 2 | B17: Bagaimana kemampuan Instruktur dalam menyampaikan program pelatihan | C17: ='KOLOM ISIAN'!C32:R32 -> 5 | D17: ='KOLOM ISIAN'!D32:S32 -> 5 | E17: ='KOLOM ISIAN'!E32:T32 -> 5 | F17: ='KOLOM ISIAN'!F32:U32 -> 5 | G17: ='KOLOM ISIAN'!G32:V32 -> 5 | H17: ='KOLOM ISIAN'!H32:W32 -> 5 | I17: ='KOLOM ISIAN'!I32:X32 -> 5 | J17: ='KOLOM ISIAN'!J32:Y32 -> 5 | ... R17: ='KOLOM ISIAN'!R32:AG32 -> 0 | S17: =SUM(C17:R17)/12 -> 5 | AC17: =IF(S17>=2.95,"BAIK",IF(S17>=1.95,"CUKUP","KURANG")) -> BAIK
A18: 3 | B18: Bagaimana kemampuan Instruktur dalam mengelola Peserta Pelatihan | C18: ='KOLOM ISIAN'!C33:R33 -> 5 | D18: ='KOLOM ISIAN'!D33:S33 -> 5 | E18: ='KOLOM ISIAN'!E33:T33 -> 4 | F18: ='KOLOM ISIAN'!F33:U33 -> 5 | G18: ='KOLOM ISIAN'!G33:V33 -> 5 | H18: ='KOLOM ISIAN'!H33:W33 -> 5 | I18: ='KOLOM ISIAN'!I33:X33 -> 4 | J18: ='KOLOM ISIAN'!J33:Y33 -> 5 | ... R18: ='KOLOM ISIAN'!R33:AG33 -> 0 | S18: =SUM(C18:R18)/12 -> 4.8333333 | AC18: =IF(S18>=2.95,"BAIK",IF(S18>=1.95,"CUKUP","KURANG")) -> BAIK
A19: 4 | B19: Bagaimana sikap, disiplin, penampilan, dan teladan Instruktur selama pelatihan | C19: ='KOLOM ISIAN'!C34:R34 -> 5 | D19: ='KOLOM ISIAN'!D34:S34 -> 5 | E19: ='KOLOM ISIAN'!E34:T34 -> 5 | F19: ='KOLOM ISIAN'!F34:U34 -> 5 | G19: ='KOLOM ISIAN'!G34:V34 -> 5 | H19: ='KOLOM ISIAN'!H34:W34 -> 5 | I19: ='KOLOM ISIAN'!I34:X34 -> 5 | J19: ='KOLOM ISIAN'!J34:Y34 -> 5 | ... R19: ='KOLOM ISIAN'!R34:AG34 -> 0 | S19: =SUM(C19:R19)/12 -> 4.9166667 | AC19: =IF(S19>=2.95,"BAIK",IF(S19>=1.95,"CUKUP","KURANG")) -> BAIK
C20: JUMLAH | S20: =AVERAGE(S16:S19) -> 4.9375 | AC20: =IF(S20>=2.95,"BAIK",IF(S20>=1.95,"CUKUP","KURANG")) -> BAIK

Sheet Penyelenggaraan
A1: KEMENTERIAN KETENAGAKERJAAN RI
A2: DIREKTORAT JENDERAL PEMBINAAN PELATIHAN DAN PRODUKTIVITAS
A3: =INSTRUKTUR!A3 -> BALAI PELATIHAN VOKASI DAN PRODUKTIVITAS
A4: Jln. DI Panjaitan No 226 Tlp. 3190427 Kendari 93117
A7: HASIL EVALUASI
A8: ='Materi Pelatihan'!A7:AC7 -> PELATIHAN KOMPETENSI BERBASIS PARIWISATA DAN INDUSTRI KREATIF
A9: ='Materi Pelatihan'!A8:AC8 -> PROGRAM PELATIHAN DASAR ASISTEN PEMBUAT PAKAIAN PAKET 2
A10: ='Materi Pelatihan'!A9:AC9 -> TGL Senin 3 Agustus S.D Jumat 28 Agustus 2026
A12: No | B12: Penyelenggaraan Penilaian | C12: Peserta (Responden Kusioner) | AC12: Keterangan
C14: 1 | D14: 2 | E14: 3 | F14: 4 | G14: 5 | H14: 6 | I14: 7 | J14: 8 | K14: 9 | L14: 10 | M14: 11 | N14: 12 | O14: 13 | P14: 14 | Q14: 15 | R14: 16 | S14: JUMLAH | T14: 22 | U14: 23 | V14: 24 | W14: 25 | X14: 26 | Y14: 27 | Z14: 28 | AA14: 29 | AB14: Jumlah
A15: IV | B15: PENYELENGGARAAN PELATIHAN
A16: 1 | B16: Bagaimana pelayanan petugas terhadap Peserta Pelatihan | C16: ='KOLOM ISIAN'!C40 -> 3 | D16: ='KOLOM ISIAN'!D40 -> 5 | E16: ='KOLOM ISIAN'!E40 -> 4 | F16: ='KOLOM ISIAN'!F40 -> 5 | G16: ='KOLOM ISIAN'!G40 -> 5 | H16: ='KOLOM ISIAN'!H40 -> 5 | I16: ='KOLOM ISIAN'!I40 -> 4 | J16: ='KOLOM ISIAN'!J40 -> 4 | ... R16: ='KOLOM ISIAN'!R40 -> 0 | S16: =SUM(C16:R16)/12 -> 4.4166667 | AC16: =IF(S16>=2.95,"BAIK",IF(S16>=1.95,"CUKUP","KURANG")) -> BAIK
A17: 2 | B17: Apakah pelaksanaan jadwal pelatihan sudah sesuai dengan rencana | C17: ='KOLOM ISIAN'!C41 -> 5 | D17: ='KOLOM ISIAN'!D41 -> 5 | E17: ='KOLOM ISIAN'!E41 -> 5 | F17: ='KOLOM ISIAN'!F41 -> 5 | G17: ='KOLOM ISIAN'!G41 -> 4 | H17: ='KOLOM ISIAN'!H41 -> 5 | I17: ='KOLOM ISIAN'!I41 -> 4 | J17: ='KOLOM ISIAN'!J41 -> 4 | ... N17: ='KOLOM ISIAN'!N41 -> 4 | O17: ='KOLOM ISIAN'!O39:AD39 -> 0 | P17: ='KOLOM ISIAN'!P39:AE39 -> 0 | Q17: ='KOLOM ISIAN'!Q39:AF39 -> 0 | R17: ='KOLOM ISIAN'!R39:AG39 -> 0 | S17: =SUM(C17:R17)/12 -> 4.5833333 | AC17: =IF(S17>=2.95,"BAIK",IF(S17>=1.95,"CUKUP","KURANG")) -> BAIK
A18: 3 | B18: Apakah perlengkapan Peserta Pelatihan (training material) diberikan tepat waktu? (contoh: atribut pelatihan/seragam/Alat Pelindung Diri/modul/materi/ATK/bahan/ konten/dll) | C18: ='KOLOM ISIAN'!C42 -> 3 | D18: ='KOLOM ISIAN'!D42 -> 5 | E18: ='KOLOM ISIAN'!E42 -> 4 | F18: ='KOLOM ISIAN'!F42 -> 5 | G18: ='KOLOM ISIAN'!G42 -> 5 | H18: ='KOLOM ISIAN'!H42 -> 3 | I18: ='KOLOM ISIAN'!I42 -> 5 | J18: ='KOLOM ISIAN'!J42 -> 4 | ... L18: ='KOLOM ISIAN'!L42 -> 5 | M18: ='KOLOM ISIAN'!M40:AB40 -> 4 | N18: ='KOLOM ISIAN'!N40:AC40 -> 5 | O18: ='KOLOM ISIAN'!O40:AD40 -> 0 | P18: ='KOLOM ISIAN'!P40:AE40 -> 0 | Q18: ='KOLOM ISIAN'!Q40:AF40 -> 0 | R18: ='KOLOM ISIAN'!R40:AG40 -> 0 | S18: =SUM(C18:R18)/12 -> 4.4166667 | AC18: =IF(S18>=2.95,"BAIK",IF(S18>=1.95,"CUKUP","KURANG")) -> BAIK
A19: 4 | B19: Apakah sarana/prasarana/fasilitas pelatihan sudah memadai?(contoh: kelas/ workshop/ mesin/alat/ website sistem manajemen pembelajaran/dll) | C19: ='KOLOM ISIAN'!C43 -> 5 | D19: ='KOLOM ISIAN'!D43 -> 5 | E19: ='KOLOM ISIAN'!E43 -> 5 | F19: ='KOLOM ISIAN'!F43 -> 5 | G19: ='KOLOM ISIAN'!G43 -> 5 | H19: ='KOLOM ISIAN'!H43 -> 4 | I19: ='KOLOM ISIAN'!I43 -> 5 | J19: ='KOLOM ISIAN'!J43 -> 5 | ... L19: ='KOLOM ISIAN'!L43 -> 5 | M19: ='KOLOM ISIAN'!M41:AB41 -> 4 | N19: ='KOLOM ISIAN'!N41:AC41 -> 4 | O19: ='KOLOM ISIAN'!O41:AD41 -> 0 | P19: ='KOLOM ISIAN'!P41:AE41 -> 0 | Q19: ='KOLOM ISIAN'!Q41:AF41 -> 0 | R19: ='KOLOM ISIAN'!R41:AG41 -> 0 | S19: =SUM(C19:R19)/12 -> 4.75 | AC19: =IF(S19>=2.95,"BAIK",IF(S19>=1.95,"CUKUP","KURANG")) -> BAIK
A20: 5 | B20: Apakah sarana/prasarana/fasilitas penunjang pelatihan sudah memadai (contoh: asrama/tempat ibadah/kantin/toilet/perpustakaan/website lembaga pelatihan/dll) | C20: ='KOLOM ISIAN'!C44 -> 5 | D20: ='KOLOM ISIAN'!D44 -> 5 | E20: ='KOLOM ISIAN'!E44 -> 5 | F20: ='KOLOM ISIAN'!F44 -> 5 | G20: ='KOLOM ISIAN'!G44 -> 5 | H20: ='KOLOM ISIAN'!H44 -> 5 | I20: ='KOLOM ISIAN'!I44 -> 4 | J20: ='KOLOM ISIAN'!J44 -> 4 | ... L20: ='KOLOM ISIAN'!L44 -> 5 | M20: ='KOLOM ISIAN'!M42:AB42 -> 2 | N20: ='KOLOM ISIAN'!N42:AC42 -> 3 | O20: ='KOLOM ISIAN'!O42:AD42 -> 0 | P20: ='KOLOM ISIAN'!P42:AE42 -> 0 | Q20: ='KOLOM ISIAN'!Q42:AF42 -> 0 | R20: ='KOLOM ISIAN'!R42:AG42 -> 0 | S20: =SUM(C20:R20)/12 -> 4.4166667 | AC20: =IF(S20>=2.95,"BAIK",IF(S20>=1.95,"CUKUP","KURANG")) -> BAIK
C21: JUMLAH | S21: =AVERAGE(S16:S20) -> 4.5166667 | AC21: =IF(S21>=2.95,"BAIK",IF(S21>=1.95,"CUKUP","KURANG")) -> BAIK

Sheet NILAI INST
A1: KEMENTERIAN KETENAGAKERJAAN RI
A2: DIREKTORAT JENDERAL PEMBINAAN PELATIHAN DAN PRODUKTIVITAS
A3: =Histogram!A3 -> BALAI PELATIHAN VOKASI DAN PRODUKTIVITAS
A4: Jln. DI Panjaitan No 226 Tlp. 3190427 Kendari 93117
A6: ='Materi Pelatihan'!$A$6:$AC$6 -> HASIL EVALUASI
A7: ='Materi Pelatihan'!A7:AC7 -> PELATIHAN KOMPETENSI BERBASIS PARIWISATA DAN INDUSTRI KREATIF
A8: ='Materi Pelatihan'!A8:AC8 -> PROGRAM PELATIHAN DASAR ASISTEN PEMBUAT PAKAIAN PAKET 2
A9: ='Materi Pelatihan'!A9:AC9 -> TGL Senin 3 Agustus S.D Jumat 28 Agustus 2026
A11: No | B11: ASPEK PENILAIAN | F11: NILAI
A14: A | B14: Penguasaan Program Pelatihan | F14: =INSTRUKTUR!S16 -> 5
A15: B | B15: Kemampuan dalam menyampaikan Program | F15: =INSTRUKTUR!S17 -> 5
A16: C | B16: Kemampuan mengelola peserta | F16: =INSTRUKTUR!S18 -> 4.8333333
A17: D | B17: Sikap, disiplin, penampilan, dan teladan Instruktur | F17: =INSTRUKTUR!S19 -> 4.9166667
A18: TOTAL PENILAIAN | F18: =AVERAGE(F14:F17) -> 4.9375
